Workbook

Sheet Model_comparison
A1: Model Name | B1: Dependent Variable | C1: Independent Variables | D1: R-squared | E1: Adj R-squared | F1: F-statistic | G1: Key coefficient | H1: P-value | I1: Significant Variables | J1: Business Usefulness | K1: Limitation | L1: Decision
A2: Simple Regression - Footfall | B2: monthly_sales | C2: footfall | D2: =Simple_regression_footfall!$E$10 -> 0.73628534 | E2: =Simple_regression_footfall!E11 -> 0.73545605 | F2: =Simple_regression_footfall!H17 -> 887.84878 | G2: =Simple_regression_footfall!E23 -> 35.678031 | H2: =Simple_regression_footfall!H23 -> 4.7503615e-94 | I2: footfall | J2: Useful because footfall directly represents customer traffic and has a clear business link to sales. | K2: Does not control for marketing, inventory, staffing, customer rating, holiday months or store type. | L2: Useful simple model
A3: Simple Regression - Marketing Spend | B3: monthly_sales | C3: marketing_spend | D3: =Simple_regression_marketing!E10 -> 0.16724469 | E3: =Simple_regression_marketing!E11 -> 0.16462596 | F3: =Simple_regression_marketing!H17 -> 63.864873 | G3: =Simple_regression_marketing!E23 -> 2.1295753 | H3: =Simple_regression_marketing!H23 -> 2.4800615e-14 | I3: marketing_spend | J3: Useful for understanding whether higher marketing spend is associated with higher sales, but it does not explain sales as strongly as footfall. | K3: Does not show whether marketing remains important after controlling for footfall and other factors. | L3: Useful simple model
A4: Simple Regression - Avg Discount | B4: monthly_sales | C4: avg_discount_pct | D4: =Simple_regression_avg_discount!E11 -> 0.008290503 | E4: =Simple_regression_avg_discount!E12 -> 0.0051719197 | F4: =Simple_regression_avg_discount!H18 -> 2.6584196 | G4: =Simple_regression_avg_discount!E24 -> -138730.45 | H4: =Simple_regression_avg_discount!H24 -> 0.10399305 | I4: None at 5% significance ( as p-value > 0.05) | J4: Limited usefulness because discounting alone explains very little variation in monthly sales. | K4: Discounts may reflect promotional pressure or weak demand, so the coefficient should not be over-interpreted. | L4: Weak simple model
A5: Multiple Regression | B5: monthly_sales | C5: footfall,marketing_spend,avg_discount_pct,inventory_availability_pct,clean_customer_rating,staff_count,holiday_flag,store_type_high_street,store_type_mall,store_type_residential | D5: =Multiple_regression!N10 -> 0.82813225 | E5: =Multiple_regression!N11 -> 0.82257019 | F5: =Multiple_regression!Q17 -> 148.8894 | G5: =Multiple_regression!N24 -> 27.90495 | H5: =Multiple_regression!Q24 -> 2.0293133e-24 | I5: marketing_spend, footfall, avg_discount_pct, inventory_availability_pct, clean_customer_rating, staff_count, holiday_flag, store_type_residential | J5: Most useful model because it compares several business drivers together and has the strongest explanatory power. | K5: Still shows association, not causation, and may miss store size, local demand, product mix, and market conditions. | L5: Final selected model

Sheet Cleaned_data
A1: store_id | B1: month | C1: region | D1: store_type | E1: marketing_spend | F1: footfall | G1: avg_discount_pct | H1: staff_count | I1: inventory_availability_pct | J1: competitor_distance_km | K1: clean_competitor_distance_km | L1: competitor_distance_missing_flag | M1: holiday_flag | N1: customer_rating | O1: clean_customer_rating | P1: customer_rating_missing_flag | Q1: monthly_sales | R1: monthly_profit
A2: STR-1001 | B2: 45658 | C2: East | D2: Residential | E2: 70389.11 | F2: 8302 | G2: 0.042 | H2: 17 | I2: 75 | J2: 5.28 | K2: =IF(ISBLANK(J2),MEDIAN($J$2:$J$321),J2) -> 5.28 | L2: =IF(ISBLANK(J2),1,0) -> 0 | M2: 1 | N2: 3.1 | O2: =IF(ISBLANK(N2),MEDIAN($N$2:$N$321),N2) -> 3.1 | P2: =IF(ISBLANK(N2),1,0) -> 0 | Q2: 658832.62 | R2: 84349.93
A3: STR-1001 | B3: 45689 | C3: East | D3: Residential | E3: 43827.89 | F3: 8487 | G3: 0.168 | H3: 23 | I3: 84.4 | J3: 4.31 | K3: =IF(ISBLANK(J3),MEDIAN($J$2:$J$321),J3) -> 4.31 | L3: =IF(ISBLANK(J3),1,0) -> 0 | M3: 0 | N3: 2.8 | O3: =IF(ISBLANK(N3),MEDIAN($N$2:$N$321),N3) -> 2.8 | P3: =IF(ISBLANK(N3),1,0) -> 0 | Q3: 634436 | R3: 106130.54
A4: STR-1001 | B4: 45717 | C4: East | D4: Residential | E4: 59921.75 | F4: 9113 | G4: 0.133 | H4: 20 | I4: 88 | J4: 12 | K4: =IF(ISBLANK(J4),MEDIAN($J$2:$J$321),J4) -> 12 | L4: =IF(ISBLANK(J4),1,0) -> 0 | M4: 0 | N4: 3.2 | O4: =IF(ISBLANK(N4),MEDIAN($N$2:$N$321),N4) -> 3.2 | P4: =IF(ISBLANK(N4),1,0) -> 0 | Q4: 678722.06 | R4: 101883.86
A5: STR-1001 | B5: 45748 | C5: East | D5: Residential | E5: 56856.63 | F5: 9431 | G5: 0.142 | H5: 23 | I5: 86.9 | J5: 4.97 | K5: =IF(ISBLANK(J5),MEDIAN($J$2:$J$321),J5) -> 4.97 | L5: =IF(ISBLANK(J5),1,0) -> 0 | M5: 0 | N5: 3.4 | O5: =IF(ISBLANK(N5),MEDIAN($N$2:$N$321),N5) -> 3.4 | P5: =IF(ISBLANK(N5),1,0) -> 0 | Q5: 658920.3 | R5: 97910.37
A6: STR-1002 | B6: 45658 | C6: East | D6: High Street | E6: 48412.64 | F6: 9545 | G6: 0.231 | H6: 21 | I6: 97.6 | J6: 6.94 | K6: =IF(ISBLANK(J6),MEDIAN($J$2:$J$321),J6) -> 6.94 | L6: =IF(ISBLANK(J6),1,0) -> 0 | M6: 1 | N6: 4.2 | O6: =IF(ISBLANK(N6),MEDIAN($N$2:$N$321),N6) -> 4.2 | P6: =IF(ISBLANK(N6),1,0) -> 0 | Q6: 741341.44 | R6: 119208.17
A7: STR-1002 | B7: 45689 | C7: East | D7: High Street | E7: 64811.21 | F7: 9792 | G7: 0.112 | H7: 20 | I7: 84.2 | J7: 2.88 | K7: =IF(ISBLANK(J7),MEDIAN($J$2:$J$321),J7) -> 2.88 | L7: =IF(ISBLANK(J7),1,0) -> 0 | M7: 0 | N7: 4.2 | O7: =IF(ISBLANK(N7),MEDIAN($N$2:$N$321),N7) -> 4.2 | P7: =IF(ISBLANK(N7),1,0) -> 0 | Q7: 761835.34 | R7: 149602.23
A8: STR-1002 | B8: 45717 | C8: East | D8: High Street | E8: 46213.45 | F8: 10616 | G8: 0.122 | H8: 22 | I8: 85.2 | J8: 0.2 | K8: =IF(ISBLANK(J8),MEDIAN($J$2:$J$321),J8) -> 0.2 | L8: =IF(ISBLANK(J8),1,0) -> 0 | M8: 1 | N8: 4.1 | O8: =IF(ISBLANK(N8),MEDIAN($N$2:$N$321),N8) -> 4.1 | P8: =IF(ISBLANK(N8),1,0) -> 0 | Q8: 806615.54 | R8: 131364.62
A9: STR-1002 | B9: 45748 | C9: East | D9: High Street | E9: 68148.52 | F9: 8567 | G9: 0.127 | H9: 23 | I9: 95.6 | J9: 0.8 | K9: =IF(ISBLANK(J9),MEDIAN($J$2:$J$321),J9) -> 0.8 | L9: =IF(ISBLANK(J9),1,0) -> 0 | M9: 0 | N9: 3.9 | O9: =IF(ISBLANK(N9),MEDIAN($N$2:$N$321),N9) -> 3.9 | P9: =IF(ISBLANK(N9),1,0) -> 0 | Q9: 850164.26 | R9: 149262.75
A10: STR-1003 | B10: 45658 | C10: North | D10: Airport | E10: 71838.86 | F10: 10979 | G10: 0.215 | H10: 26 | I10: 88.6 | J10: 7.7 | K10: =IF(ISBLANK(J10),MEDIAN($J$2:$J$321),J10) -> 7.7 | L10: =IF(ISBLANK(J10),1,0) -> 0 | M10: 1 | N10: 3.8 | O10: =IF(ISBLANK(N10),MEDIAN($N$2:$N$321),N10) -> 3.8 | P10: =IF(ISBLANK(N10),1,0) -> 0 | Q10: 930581.7 | R10: 136207.98
A11: STR-1003 | B11: 45689 | C11: North | D11: Airport | E11: 68133.44 | F11: 9459 | G11: 0.22 | H11: 21 | I11: 85 | J11: 1.91 | K11: =IF(ISBLANK(J11),MEDIAN($J$2:$J$321),J11) -> 1.91 | L11: =IF(ISBLANK(J11),1,0) -> 0 | M11: 0 | N11: 4.2 | O11: =IF(ISBLANK(N11),MEDIAN($N$2:$N$321),N11) -> 4.2 | P11: =IF(ISBLANK(N11),1,0) -> 0 | Q11: 779010.94 | R11: 106328.09
A12: STR-1003 | B12: 45717 | C12: North | D12: Airport | E12: 34285.21 | F12: 9172 | G12: 0.213 | H12: 22 | I12: 88.3 | J12: 10.46 | K12: =IF(ISBLANK(J12),MEDIAN($J$2:$J$321),J12) -> 10.46 | L12: =IF(ISBLANK(J12),1,0) -> 0 | M12: 1 | N12: 3.8 | O12: =IF(ISBLANK(N12),MEDIAN($N$2:$N$321),N12) -> 3.8 | P12: =IF(ISBLANK(N12),1,0) -> 0 | Q12: 723060.76 | R12: 123131.24
A13: STR-1003 | B13: 45748 | C13: North | D13: Airport | E13: 67979.88 | F13: 11230 | G13: 0.002 | H13: 28 | I13: 85.3 | J13: 7.16 | K13: =IF(ISBLANK(J13),MEDIAN($J$2:$J$321),J13) -> 7.16 | L13: =IF(ISBLANK(J13),1,0) -> 0 | M13: 0 | N13: 3.8 | O13: =IF(ISBLANK(N13),MEDIAN($N$2:$N$321),N13) -> 3.8 | P13: =IF(ISBLANK(N13),1,0) -> 0 | Q13: 910791.94 | R13: 158891.28
... A34: STR-1009 | B34: 45658 | C34: North | D34: Residential | E34: 54597.83 | F34: 9429 | G34: 0.188 | H34: 21 | I34: 83.3 | J34: 11.71 | K34: =IF(ISBLANK(J34),MEDIAN($J$2:$J$321),J34) -> 11.71 | L34: =IF(ISBLANK(J34),1,0) -> 0 | M34: 0 | N34: 4.2 | O34: =IF(ISBLANK(N34),MEDIAN($N$2:$N$321),N34) -> 4.2 | P34: =IF(ISBLANK(N34),1,0) -> 0 | Q34: 641865.03 | R34: 81342.58
A35: STR-1009 | B35: 45689 | C35: North | D35: Residential | E35: 73771.91 | F35: 11695 | G35: 0.07 | H35: 25 | I35: 84.7 | J35: 0.62 | K35: =IF(ISBLANK(J35),MEDIAN($J$2:$J$321),J35) -> 0.62 | L35: =IF(ISBLANK(J35),1,0) -> 0 | M35: 0 | O35: =IF(ISBLANK(N35),MEDIAN($N$2:$N$321),N35) -> 3.9 | P35: =IF(ISBLANK(N35),1,0) -> 1 | Q35: 799477.76 | R35: 164974.41
A36: STR-1009 | B36: 45717 | C36: North | D36: Residential | E36: 74413.88 | F36: 9449 | G36: 0.039 | H36: 23 | I36: 92.1 | J36: 2.12 | K36: =IF(ISBLANK(J36),MEDIAN($J$2:$J$321),J36) -> 2.12 | L36: =IF(ISBLANK(J36),1,0) -> 0 | M36: 0 | N36: 3.5 | O36: =IF(ISBLANK(N36),MEDIAN($N$2:$N$321),N36) -> 3.5 | P36: =IF(ISBLANK(N36),1,0) -> 0 | Q36: 798952.17 | R36: 161499.04
A37: STR-1009 | B37: 45748 | C37: North | D37: Residential | E37: 52483.77 | F37: 10453 | G37: 0.247 | H37: 25 | I37: 99 | J37: 6.31 | K37: =IF(ISBLANK(J37),MEDIAN($J$2:$J$321),J37) -> 6.31 | L37: =IF(ISBLANK(J37),1,0) -> 0 | M37: 0 | N37: 3.6 | O37: =IF(ISBLANK(N37),MEDIAN($N$2:$N$321),N37) -> 3.6 | P37: =IF(ISBLANK(N37),1,0) -> 0 | Q37: 800979.78 | R37: 149242.27
A38: STR-1010 | B38: 45658 | C38: North | D38: Mall | E38: 75269.87 | F38: 8838 | G38: 0.092 | H38: 21 | I38: 83.1 | J38: 9.56 | K38: =IF(ISBLANK(J38),MEDIAN($J$2:$J$321),J38) -> 9.56 | L38: =IF(ISBLANK(J38),1,0) -> 0 | M38: 1 | N38: 4.2 | O38: =IF(ISBLANK(N38),MEDIAN($N$2:$N$321),N38) -> 4.2 | P38: =IF(ISBLANK(N38),1,0) -> 0 | Q38: 820593.93 | R38: 115860.06
A39: STR-1010 | B39: 45689 | C39: North | D39: Mall | E39: 61245.41 | F39: 8156 | G39: 0.156 | H39: 19 | I39: 92.9 | J39: 9.05 | K39: =IF(ISBLANK(J39),MEDIAN($J$2:$J$321),J39) -> 9.05 | L39: =IF(ISBLANK(J39),1,0) -> 0 | M39: 0 | N39: 3.8 | O39: =IF(ISBLANK(N39),MEDIAN($N$2:$N$321),N39) -> 3.8 | P39: =IF(ISBLANK(N39),1,0) -> 0 | Q39: 718330.53 | R39: 93247.9
A40: STR-1010 | B40: 45717 | C40: North | D40: Mall | E40: 93381.26 | F40: 7562 | G40: 0.198 | H40: 19 | I40: 82.9 | J40: 5.05 | K40: =IF(ISBLANK(J40),MEDIAN($J$2:$J$321),J40) -> 5.05 | L40: =IF(ISBLANK(J40),1,0) -> 0 | M40: 0 | N40: 4 | O40: =IF(ISBLANK(N40),MEDIAN($N$2:$N$321),N40) -> 4 | P40: =IF(ISBLANK(N40),1,0) -> 0 | Q40: 736633.4 | R40: 115654.66
A41: STR-1010 | B41: 45748 | C41: North | D41: Mall | E41: 65012.19 | F41: 9598 | G41: 0.085 | H41: 24 | I41: 98.3 | J41: 0.89 | K41: =IF(ISBLANK(J41),MEDIAN($J$2:$J$321),J41) -> 0.89 | L41: =IF(ISBLANK(J41),1,0) -> 0 | M41: 0 | N41: 3.8 | O41: =IF(ISBLANK(N41),MEDIAN($N$2:$N$321),N41) -> 3.8 | P41: =IF(ISBLANK(N41),1,0) -> 0 | Q41: 828623.85 | R41: 167320.52
A42: STR-1011 | B42: 45658 | C42: East | D42: Mall | E42: 40462.94 | F42: 3660 | G42: 0.218 | H42: 11 | I42: 95.2 | J42: 5.57 | K42: =IF(ISBLANK(J42),MEDIAN($J$2:$J$321),J42) -> 5.57 | L42: =IF(ISBLANK(J42),1,0) -> 0 | M42: 0 | N42: 4.4 | O42: =IF(ISBLANK(N42),MEDIAN($N$2:$N$321),N42) -> 4.4 | P42: =IF(ISBLANK(N42),1,0) -> 0 | Q42: 592195.85 | R42: 92291.56
A43: STR-1011 | B43: 45689 | C43: East | D43: Mall | E43: 46123.88 | F43: 3227 | G43: 0.143 | H43: 10 | I43: 75.4 | J43: 1.06 | K43: =IF(ISBLANK(J43),MEDIAN($J$2:$J$321),J43) -> 1.06 | L43: =IF(ISBLANK(J43),1,0) -> 0 | M43: 0 | N43: 4.4 | O43: =IF(ISBLANK(N43),MEDIAN($N$2:$N$321),N43) -> 4.4 | P43: =IF(ISBLANK(N43),1,0) -> 0 | Q43: 532644.46 | R43: 60681.32
A44: STR-1011 | B44: 45717 | C44: East | D44: Mall | E44: 68077.54 | F44: 3360 | G44: 0.128 | H44: 14 | I44: 88.2 | J44: 1.24 | K44: =IF(ISBLANK(J44),MEDIAN($J$2:$J$321),J44) -> 1.24 | L44: =IF(ISBLANK(J44),1,0) -> 0 | M44: 1 | N44: 4 | O44: =IF(ISBLANK(N44),MEDIAN($N$2:$N$321),N44) -> 4 | P44: =IF(ISBLANK(N44),1,0) -> 0 | Q44: 657429.18 | R44: 88919.74
A45: STR-1011 | B45: 45748 | C45: East | D45: Mall | E45: 64882.14 | F45: 3642 | G45: 0.019 | H45: 13 | I45: 87.8 | J45: 4.52 | K45: =IF(ISBLANK(J45),MEDIAN($J$2:$J$321),J45) -> 4.52 | L45: =IF(ISBLANK(J45),1,0) -> 0 | M45: 0 | N45: 4.2 | O45: =IF(ISBLANK(N45),MEDIAN($N$2:$N$321),N45) -> 4.2 | P45: =IF(ISBLANK(N45),1,0) -> 0 | Q45: 605178 | R45: 106958.74
A46: STR-1012 | B46: 45658 | C46: West | D46: Residential | E46: 138855.51 | F46: 5145 | G46: 0.06 | H46: 17 | I46: 88.2 | J46: 9.58 | K46: =IF(ISBLANK(J46),MEDIAN($J$2:$J$321),J46) -> 9.58 | L46: =IF(ISBLANK(J46),1,0) -> 0 | M46: 0 | N46: 3.2 | O46: =IF(ISBLANK(N46),MEDIAN($N$2:$N$321),N46) -> 3.2 | P46: =IF(ISBLANK(N46),1,0) -> 0 | Q46: 595467.6 | R46: 104276.46
A47: STR-1012 | B47: 45689 | C47: West | D47: Residential | E47: 63630.21 | F47: 4460 | G47: 0.235 | H47: 14 | I47: 98.6 | J47: 5.52 | K47: =IF(ISBLANK(J47),MEDIAN($J$2:$J$321),J47) -> 5.52 | L47: =IF(ISBLANK(J47),1,0) -> 0 | M47: 0 | N47: 3.5 | O47: =IF(ISBLANK(N47),MEDIAN($N$2:$N$321),N47) -> 3.5 | P47: =IF(ISBLANK(N47),1,0) -> 0 | Q47: 599603.4 | R47: 112685.12
... A72: STR-1018 | B72: 45717 | C72: East | D72: High Street | E72: 60571.82 | F72: 3193 | G72: 0.197 | H72: 7 | I72: 99 | J72: 1.43 | K72: =IF(ISBLANK(J72),MEDIAN($J$2:$J$321),J72) -> 1.43 | L72: =IF(ISBLANK(J72),1,0) -> 0 | M72: 0 | N72: 3.2 | O72: =IF(ISBLANK(N72),MEDIAN($N$2:$N$321),N72) -> 3.2 | P72: =IF(ISBLANK(N72),1,0) -> 0 | Q72: 605023.87 | R72: 98545.81
A73: STR-1018 | B73: 45748 | C73: East | D73: High Street | E73: 55081.16 | F73: 5485 | G73: 0.036 | H73: 12 | I73: 88 | K73: =IF(ISBLANK(J73),MEDIAN($J$2:$J$321),J73) -> 3.365 | L73: =IF(ISBLANK(J73),1,0) -> 1 | M73: 0 | N73: 3.5 | O73: =IF(ISBLANK(N73),MEDIAN($N$2:$N$321),N73) -> 3.5 | P73: =IF(ISBLANK(N73),1,0) -> 0 | Q73: 674774.09 | R73: 141917.59
A74: STR-1019 | B74: 45658 | C74: East | D74: Residential | E74: 46201.46 | F74: 5918 | G74: 0.277 | H74: 13 | I74: 78.8 | J74: 4.91 | K74: =IF(ISBLANK(J74),MEDIAN($J$2:$J$321),J74) -> 4.91 | L74: =IF(ISBLANK(J74),1,0) -> 0 | M74: 0 | N74: 4.5 | O74: =IF(ISBLANK(N74),MEDIAN($N$2:$N$321),N74) -> 4.5 | P74: =IF(ISBLANK(N74),1,0) -> 0 | Q74: 616069.41 | R74: 54453.99
A75: STR-1019 | B75: 45689 | C75: East | D75: Residential | E75: 53762.92 | F75: 6821 | G75: 0.066 | H75: 19 | I75: 94.6 | J75: 7.03 | K75: =IF(ISBLANK(J75),MEDIAN($J$2:$J$321),J75) -> 7.03 | L75: =IF(ISBLANK(J75),1,0) -> 0 | M75: 0 | N75: 4.4 | O75: =IF(ISBLANK(N75),MEDIAN($N$2:$N$321),N75) -> 4.4 | P75: =IF(ISBLANK(N75),1,0) -> 0 | Q75: 630829.94 | R75: 117090.02
A76: STR-1019 | B76: 45717 | C76: East | D76: Residential | E76: 70144.78 | F76: 6806 | G76: 0.178 | H76: 20 | I76: 93.1 | J76: 0.28 | K76: =IF(ISBLANK(J76),MEDIAN($J$2:$J$321),J76) -> 0.28 | L76: =IF(ISBLANK(J76),1,0) -> 0 | M76: 1 | N76: 4.3 | O76: =IF(ISBLANK(N76),MEDIAN($N$2:$N$321),N76) -> 4.3 | P76: =IF(ISBLANK(N76),1,0) -> 0 | Q76: 788087.68 | R76: 116803.42
A77: STR-1019 | B77: 45748 | C77: East | D77: Residential | E77: 58749.63 | F77: 8252 | G77: 0.203 | H77: 20 | I77: 85.2 | J77: 3.61 | K77: =IF(ISBLANK(J77),MEDIAN($J$2:$J$321),J77) -> 3.61 | L77: =IF(ISBLANK(J77),1,0) -> 0 | M77: 0 | N77: 4.5 | O77: =IF(ISBLANK(N77),MEDIAN($N$2:$N$321),N77) -> 4.5 | P77: =IF(ISBLANK(N77),1,0) -> 0 | Q77: 680840.36 | R77: 68007.68
A78: STR-1020 | B78: 45658 | C78: South | D78: High Street | E78: 56973.18 | F78: 6662 | G78: 0.1 | H78: 15 | I78: 77.7 | J78: 7.52 | K78: =IF(ISBLANK(J78),MEDIAN($J$2:$J$321),J78) -> 7.52 | L78: =IF(ISBLANK(J78),1,0) -> 0 | M78: 1 | N78: 3.2 | O78: =IF(ISBLANK(N78),MEDIAN($N$2:$N$321),N78) -> 3.2 | P78: =IF(ISBLANK(N78),1,0) -> 0 | Q78: 643657.47 | R78: 87022.45
A79: STR-1020 | B79: 45689 | C79: South | D79: High Street | E79: 54872.82 | F79: 5962 | G79: 0.064 | H79: 12 | I79: 85.4 | J79: 2.58 | K79: =IF(ISBLANK(J79),MEDIAN($J$2:$J$321),J79) -> 2.58 | L79: =IF(ISBLANK(J79),1,0) -> 0 | M79: 0 | N79: 2.9 | O79: =IF(ISBLANK(N79),MEDIAN($N$2:$N$321),N79) -> 2.9 | P79: =IF(ISBLANK(N79),1,0) -> 0 | Q79: 691112.6 | R79: 109212.83
A80: STR-1020 | B80: 45717 | C80: South | D80: High Street | E80: 80562.81 | F80: 7470 | G80: 0.172 | H80: 16 | I80: 83.5 | J80: 2.29 | K80: =IF(ISBLANK(J80),MEDIAN($J$2:$J$321),J80) -> 2.29 | L80: =IF(ISBLANK(J80),1,0) -> 0 | M80: 0 | N80: 3.3 | O80: =IF(ISBLANK(N80),MEDIAN($N$2:$N$321),N80) -> 3.3 | P80: =IF(ISBLANK(N80),1,0) -> 0 | Q80: 776922.17 | R80: 150701.93
A81: STR-1020 | B81: 45748 | C81: South | D81: High Street | E81: 77999.9 | F81: 5974 | G81: 0.252 | H81: 14 | I81: 81.3 | J81: 2.39 | K81: =IF(ISBLANK(J81),MEDIAN($J$2:$J$321),J81) -> 2.39 | L81: =IF(ISBLANK(J81),1,0) -> 0 | M81: 0 | N81: 3.2 | O81: =IF(ISBLANK(N81),MEDIAN($N$2:$N$321),N81) -> 3.2 | P81: =IF(ISBLANK(N81),1,0) -> 0 | Q81: 636561.34 | R81: 93861.06
A82: STR-1021 | B82: 45658 | C82: West | D82: Mall | E82: 60881.01 | F82: 5410 | G82: 0.179 | H82: 15 | I82: 83.9 | J82: 5.24 | K82: =IF(ISBLANK(J82),MEDIAN($J$2:$J$321),J82) -> 5.24 | L82: =IF(ISBLANK(J82),1,0) -> 0 | M82: 0 | N82: 4.6 | O82: =IF(ISBLANK(N82),MEDIAN($N$2:$N$321),N82) -> 4.6 | P82: =IF(ISBLANK(N82),1,0) -> 0 | Q82: 621369.58 | R82: 85493.64
A83: STR-1021 | B83: 45689 | C83: West | D83: Mall | E83: 60628.38 | F83: 4451 | G83: 0.095 | H83: 10 | I83: 89.6 | J83: 3.17 | K83: =IF(ISBLANK(J83),MEDIAN($J$2:$J$321),J83) -> 3.17 | L83: =IF(ISBLANK(J83),1,0) -> 0 | M83: 0 | N83: 4.6 | O83: =IF(ISBLANK(N83),MEDIAN($N$2:$N$321),N83) -> 4.6 | P83: =IF(ISBLANK(N83),1,0) -> 0 | Q83: 682208.01 | R83: 110318.84
A84: STR-1021 | B84: 45717 | C84: West | D84: Mall | E84: 72731.14 | F84: 4644 | G84: 0.084 | H84: 15 | I84: 87.1 | J84: 2.66 | K84: =IF(ISBLANK(J84),MEDIAN($J$2:$J$321),J84) -> 2.66 | L84: =IF(ISBLANK(J84),1,0) -> 0 | M84: 0 | N84: 4.6 | O84: =IF(ISBLANK(N84),MEDIAN($N$2:$N$321),N84) -> 4.6 | P84: =IF(ISBLANK(N84),1,0) -> 0 | Q84: 727241.86 | R84: 155810.3
...

Sheet Dummy_variables
A1: store_id | B1: month | C1: region | D1: store_type | E1: marketing_spend | F1: footfall | G1: avg_discount_pct | H1: staff_count | I1: inventory_availability_pct | J1: competitor_distance_km | K1: clean_competitor_distance_km | L1: competitor_distance_missing_flag | M1: holiday_flag | N1: customer_rating | O1: clean_customer_rating | P1: customer_rating_missing_flag | Q1: monthly_sales | R1: monthly_profit | S1: store_type_high_street | T1: store_type_mall | U1: store_type_residential | V1: region_north | W1: region_south | X1: region_west | Y1: region_east
A2: STR-1001 | B2: 45658 | C2: East | D2: Residential | E2: 70389.11 | F2: 8302 | G2: 0.042 | H2: 17 | I2: 75 | J2: 5.28 | K2: =IF(ISBLANK(J2),MEDIAN($J$2:$J$321),J2) -> 5.28 | L2: =IF(ISBLANK(J2),1,0) -> 0 | M2: 1 | N2: 3.1 | O2: =IF(ISBLANK(N2),MEDIAN($N$2:$N$321),N2) -> 3.1 | P2: =IF(ISBLANK(N2),1,0) -> 0 | Q2: 658832.62 | R2: 84349.93 | S2: =IF(D2="High Street",1,0) -> 0 | T2: =IF(D2="Mall",1,0) -> 0 | U2: =IF(D2="Residential",1,0) -> 1 | V2: =IF(C2="North",1,0) -> 0 | W2: =IF(C2="South",1,0) -> 0 | X2: =IF(C2="West",1,0) -> 0 | Y2: =IF(C2="East",1,0) -> 1
A3: STR-1001 | B3: 45689 | C3: East | D3: Residential | E3: 43827.89 | F3: 8487 | G3: 0.168 | H3: 23 | I3: 84.4 | J3: 4.31 | K3: =IF(ISBLANK(J3),MEDIAN($J$2:$J$321),J3) -> 4.31 | L3: =IF(ISBLANK(J3),1,0) -> 0 | M3: 0 | N3: 2.8 | O3: =IF(ISBLANK(N3),MEDIAN($N$2:$N$321),N3) -> 2.8 | P3: =IF(ISBLANK(N3),1,0) -> 0 | Q3: 634436 | R3: 106130.54 | S3: =IF(D3="High Street",1,0) -> 0 | T3: =IF(D3="Mall",1,0) -> 0 | U3: =IF(D3="Residential",1,0) -> 1 | V3: =IF(C3="North",1,0) -> 0 | W3: =IF(C3="South",1,0) -> 0 | X3: =IF(C3="West",1,0) -> 0 | Y3: =IF(C3="East",1,0) -> 1
A4: STR-1001 | B4: 45717 | C4: East | D4: Residential | E4: 59921.75 | F4: 9113 | G4: 0.133 | H4: 20 | I4: 88 | J4: 12 | K4: =IF(ISBLANK(J4),MEDIAN($J$2:$J$321),J4) -> 12 | L4: =IF(ISBLANK(J4),1,0) -> 0 | M4: 0 | N4: 3.2 | O4: =IF(ISBLANK(N4),MEDIAN($N$2:$N$321),N4) -> 3.2 | P4: =IF(ISBLANK(N4),1,0) -> 0 | Q4: 678722.06 | R4: 101883.86 | S4: =IF(D4="High Street",1,0) -> 0 | T4: =IF(D4="Mall",1,0) -> 0 | U4: =IF(D4="Residential",1,0) -> 1 | V4: =IF(C4="North",1,0) -> 0 | W4: =IF(C4="South",1,0) -> 0 | X4: =IF(C4="West",1,0) -> 0 | Y4: =IF(C4="East",1,0) -> 1
A5: STR-1001 | B5: 45748 | C5: East | D5: Residential | E5: 56856.63 | F5: 9431 | G5: 0.142 | H5: 23 | I5: 86.9 | J5: 4.97 | K5: =IF(ISBLANK(J5),MEDIAN($J$2:$J$321),J5) -> 4.97 | L5: =IF(ISBLANK(J5),1,0) -> 0 | M5: 0 | N5: 3.4 | O5: =IF(ISBLANK(N5),MEDIAN($N$2:$N$321),N5) -> 3.4 | P5: =IF(ISBLANK(N5),1,0) -> 0 | Q5: 658920.3 | R5: 97910.37 | S5: =IF(D5="High Street",1,0) -> 0 | T5: =IF(D5="Mall",1,0) -> 0 | U5: =IF(D5="Residential",1,0) -> 1 | V5: =IF(C5="North",1,0) -> 0 | W5: =IF(C5="South",1,0) -> 0 | X5: =IF(C5="West",1,0) -> 0 | Y5: =IF(C5="East",1,0) -> 1
A6: STR-1002 | B6: 45658 | C6: East | D6: High Street | E6: 48412.64 | F6: 9545 | G6: 0.231 | H6: 21 | I6: 97.6 | J6: 6.94 | K6: =IF(ISBLANK(J6),MEDIAN($J$2:$J$321),J6) -> 6.94 | L6: =IF(ISBLANK(J6),1,0) -> 0 | M6: 1 | N6: 4.2 | O6: =IF(ISBLANK(N6),MEDIAN($N$2:$N$321),N6) -> 4.2 | P6: =IF(ISBLANK(N6),1,0) -> 0 | Q6: 741341.44 | R6: 119208.17 | S6: =IF(D6="High Street",1,0) -> 1 | T6: =IF(D6="Mall",1,0) -> 0 | U6: =IF(D6="Residential",1,0) -> 0 | V6: =IF(C6="North",1,0) -> 0 | W6: =IF(C6="South",1,0) -> 0 | X6: =IF(C6="West",1,0) -> 0 | Y6: =IF(C6="East",1,0) -> 1
A7: STR-1002 | B7: 45689 | C7: East | D7: High Street | E7: 64811.21 | F7: 9792 | G7: 0.112 | H7: 20 | I7: 84.2 | J7: 2.88 | K7: =IF(ISBLANK(J7),MEDIAN($J$2:$J$321),J7) -> 2.88 | L7: =IF(ISBLANK(J7),1,0) -> 0 | M7: 0 | N7: 4.2 | O7: =IF(ISBLANK(N7),MEDIAN($N$2:$N$321),N7) -> 4.2 | P7: =IF(ISBLANK(N7),1,0) -> 0 | Q7: 761835.34 | R7: 149602.23 | S7: =IF(D7="High Street",1,0) -> 1 | T7: =IF(D7="Mall",1,0) -> 0 | U7: =IF(D7="Residential",1,0) -> 0 | V7: =IF(C7="North",1,0) -> 0 | W7: =IF(C7="South",1,0) -> 0 | X7: =IF(C7="West",1,0) -> 0 | Y7: =IF(C7="East",1,0) -> 1
A8: STR-1002 | B8: 45717 | C8: East | D8: High Street | E8: 46213.45 | F8: 10616 | G8: 0.122 | H8: 22 | I8: 85.2 | J8: 0.2 | K8: =IF(ISBLANK(J8),MEDIAN($J$2:$J$321),J8) -> 0.2 | L8: =IF(ISBLANK(J8),1,0) -> 0 | M8: 1 | N8: 4.1 | O8: =IF(ISBLANK(N8),MEDIAN($N$2:$N$321),N8) -> 4.1 | P8: =IF(ISBLANK(N8),1,0) -> 0 | Q8: 806615.54 | R8: 131364.62 | S8: =IF(D8="High Street",1,0) -> 1 | T8: =IF(D8="Mall",1,0) -> 0 | U8: =IF(D8="Residential",1,0) -> 0 | V8: =IF(C8="North",1,0) -> 0 | W8: =IF(C8="South",1,0) -> 0 | X8: =IF(C8="West",1,0) -> 0 | Y8: =IF(C8="East",1,0) -> 1
A9: STR-1002 | B9: 45748 | C9: East | D9: High Street | E9: 68148.52 | F9: 8567 | G9: 0.127 | H9: 23 | I9: 95.6 | J9: 0.8 | K9: =IF(ISBLANK(J9),MEDIAN($J$2:$J$321),J9) -> 0.8 | L9: =IF(ISBLANK(J9),1,0) -> 0 | M9: 0 | N9: 3.9 | O9: =IF(ISBLANK(N9),MEDIAN($N$2:$N$321),N9) -> 3.9 | P9: =IF(ISBLANK(N9),1,0) -> 0 | Q9: 850164.26 | R9: 149262.75 | S9: =IF(D9="High Street",1,0) -> 1 | T9: =IF(D9="Mall",1,0) -> 0 | U9: =IF(D9="Residential",1,0) -> 0 | V9: =IF(C9="North",1,0) -> 0 | W9: =IF(C9="South",1,0) -> 0 | X9: =IF(C9="West",1,0) -> 0 | Y9: =IF(C9="East",1,0) -> 1
A10: STR-1003 | B10: 45658 | C10: North | D10: Airport | E10: 71838.86 | F10: 10979 | G10: 0.215 | H10: 26 | I10: 88.6 | J10: 7.7 | K10: =IF(ISBLANK(J10),MEDIAN($J$2:$J$321),J10) -> 7.7 | L10: =IF(ISBLANK(J10),1,0) -> 0 | M10: 1 | N10: 3.8 | O10: =IF(ISBLANK(N10),MEDIAN($N$2:$N$321),N10) -> 3.8 | P10: =IF(ISBLANK(N10),1,0) -> 0 | Q10: 930581.7 | R10: 136207.98 | S10: =IF(D10="High Street",1,0) -> 0 | T10: =IF(D10="Mall",1,0) -> 0 | U10: =IF(D10="Residential",1,0) -> 0 | V10: =IF(C10="North",1,0) -> 1 | W10: =IF(C10="South",1,0) -> 0 | X10: =IF(C10="West",1,0) -> 0 | Y10: =IF(C10="East",1,0) -> 0
A11: STR-1003 | B11: 45689 | C11: North | D11: Airport | E11: 68133.44 | F11: 9459 | G11: 0.22 | H11: 21 | I11: 85 | J11: 1.91 | K11: =IF(ISBLANK(J11),MEDIAN($J$2:$J$321),J11) -> 1.91 | L11: =IF(ISBLANK(J11),1,0) -> 0 | M11: 0 | N11: 4.2 | O11: =IF(ISBLANK(N11),MEDIAN($N$2:$N$321),N11) -> 4.2 | P11: =IF(ISBLANK(N11),1,0) -> 0 | Q11: 779010.94 | R11: 106328.09 | S11: =IF(D11="High Street",1,0) -> 0 | T11: =IF(D11="Mall",1,0) -> 0 | U11: =IF(D11="Residential",1,0) -> 0 | V11: =IF(C11="North",1,0) -> 1 | W11: =IF(C11="South",1,0) -> 0 | X11: =IF(C11="West",1,0) -> 0 | Y11: =IF(C11="East",1,0) -> 0
A12: STR-1003 | B12: 45717 | C12: North | D12: Airport | E12: 34285.21 | F12: 9172 | G12: 0.213 | H12: 22 | I12: 88.3 | J12: 10.46 | K12: =IF(ISBLANK(J12),MEDIAN($J$2:$J$321),J12) -> 10.46 | L12: =IF(ISBLANK(J12),1,0) -> 0 | M12: 1 | N12: 3.8 | O12: =IF(ISBLANK(N12),MEDIAN($N$2:$N$321),N12) -> 3.8 | P12: =IF(ISBLANK(N12),1,0) -> 0 | Q12: 723060.76 | R12: 123131.24 | S12: =IF(D12="High Street",1,0) -> 0 | T12: =IF(D12="Mall",1,0) -> 0 | U12: =IF(D12="Residential",1,0) -> 0 | V12: =IF(C12="North",1,0) -> 1 | W12: =IF(C12="South",1,0) -> 0 | X12: =IF(C12="West",1,0) -> 0 | Y12: =IF(C12="East",1,0) -> 0
A13: STR-1003 | B13: 45748 | C13: North | D13: Airport | E13: 67979.88 | F13: 11230 | G13: 0.002 | H13: 28 | I13: 85.3 | J13: 7.16 | K13: =IF(ISBLANK(J13),MEDIAN($J$2:$J$321),J13) -> 7.16 | L13: =IF(ISBLANK(J13),1,0) -> 0 | M13: 0 | N13: 3.8 | O13: =IF(ISBLANK(N13),MEDIAN($N$2:$N$321),N13) -> 3.8 | P13: =IF(ISBLANK(N13),1,0) -> 0 | Q13: 910791.94 | R13: 158891.28 | S13: =IF(D13="High Street",1,0) -> 0 | T13: =IF(D13="Mall",1,0) -> 0 | U13: =IF(D13="Residential",1,0) -> 0 | V13: =IF(C13="North",1,0) -> 1 | W13: =IF(C13="South",1,0) -> 0 | X13: =IF(C13="West",1,0) -> 0 | Y13: =IF(C13="East",1,0) -> 0
... A34: STR-1009 | B34: 45658 | C34: North | D34: Residential | E34: 54597.83 | F34: 9429 | G34: 0.188 | H34: 21 | I34: 83.3 | J34: 11.71 | K34: =IF(ISBLANK(J34),MEDIAN($J$2:$J$321),J34) -> 11.71 | L34: =IF(ISBLANK(J34),1,0) -> 0 | M34: 0 | N34: 4.2 | O34: =IF(ISBLANK(N34),MEDIAN($N$2:$N$321),N34) -> 4.2 | P34: =IF(ISBLANK(N34),1,0) -> 0 | Q34: 641865.03 | R34: 81342.58 | S34: =IF(D34="High Street",1,0) -> 0 | T34: =IF(D34="Mall",1,0) -> 0 | U34: =IF(D34="Residential",1,0) -> 1 | V34: =IF(C34="North",1,0) -> 1 | W34: =IF(C34="South",1,0) -> 0 | X34: =IF(C34="West",1,0) -> 0 | Y34: =IF(C34="East",1,0) -> 0
A35: STR-1009 | B35: 45689 | C35: North | D35: Residential | E35: 73771.91 | F35: 11695 | G35: 0.07 | H35: 25 | I35: 84.7 | J35: 0.62 | K35: =IF(ISBLANK(J35),MEDIAN($J$2:$J$321),J35) -> 0.62 | L35: =IF(ISBLANK(J35),1,0) -> 0 | M35: 0 | O35: =IF(ISBLANK(N35),MEDIAN($N$2:$N$321),N35) -> 3.9 | P35: =IF(ISBLANK(N35),1,0) -> 1 | Q35: 799477.76 | R35: 164974.41 | S35: =IF(D35="High Street",1,0) -> 0 | T35: =IF(D35="Mall",1,0) -> 0 | U35: =IF(D35="Residential",1,0) -> 1 | V35: =IF(C35="North",1,0) -> 1 | W35: =IF(C35="South",1,0) -> 0 | X35: =IF(C35="West",1,0) -> 0 | Y35: =IF(C35="East",1,0) -> 0
A36: STR-1009 | B36: 45717 | C36: North | D36: Residential | E36: 74413.88 | F36: 9449 | G36: 0.039 | H36: 23 | I36: 92.1 | J36: 2.12 | K36: =IF(ISBLANK(J36),MEDIAN($J$2:$J$321),J36) -> 2.12 | L36: =IF(ISBLANK(J36),1,0) -> 0 | M36: 0 | N36: 3.5 | O36: =IF(ISBLANK(N36),MEDIAN($N$2:$N$321),N36) -> 3.5 | P36: =IF(ISBLANK(N36),1,0) -> 0 | Q36: 798952.17 | R36: 161499.04 | S36: =IF(D36="High Street",1,0) -> 0 | T36: =IF(D36="Mall",1,0) -> 0 | U36: =IF(D36="Residential",1,0) -> 1 | V36: =IF(C36="North",1,0) -> 1 | W36: =IF(C36="South",1,0) -> 0 | X36: =IF(C36="West",1,0) -> 0 | Y36: =IF(C36="East",1,0) -> 0
A37: STR-1009 | B37: 45748 | C37: North | D37: Residential | E37: 52483.77 | F37: 10453 | G37: 0.247 | H37: 25 | I37: 99 | J37: 6.31 | K37: =IF(ISBLANK(J37),MEDIAN($J$2:$J$321),J37) -> 6.31 | L37: =IF(ISBLANK(J37),1,0) -> 0 | M37: 0 | N37: 3.6 | O37: =IF(ISBLANK(N37),MEDIAN($N$2:$N$321),N37) -> 3.6 | P37: =IF(ISBLANK(N37),1,0) -> 0 | Q37: 800979.78 | R37: 149242.27 | S37: =IF(D37="High Street",1,0) -> 0 | T37: =IF(D37="Mall",1,0) -> 0 | U37: =IF(D37="Residential",1,0) -> 1 | V37: =IF(C37="North",1,0) -> 1 | W37: =IF(C37="South",1,0) -> 0 | X37: =IF(C37="West",1,0) -> 0 | Y37: =IF(C37="East",1,0) -> 0
A38: STR-1010 | B38: 45658 | C38: North | D38: Mall | E38: 75269.87 | F38: 8838 | G38: 0.092 | H38: 21 | I38: 83.1 | J38: 9.56 | K38: =IF(ISBLANK(J38),MEDIAN($J$2:$J$321),J38) -> 9.56 | L38: =IF(ISBLANK(J38),1,0) -> 0 | M38: 1 | N38: 4.2 | O38: =IF(ISBLANK(N38),MEDIAN($N$2:$N$321),N38) -> 4.2 | P38: =IF(ISBLANK(N38),1,0) -> 0 | Q38: 820593.93 | R38: 115860.06 | S38: =IF(D38="High Street",1,0) -> 0 | T38: =IF(D38="Mall",1,0) -> 1 | U38: =IF(D38="Residential",1,0) -> 0 | V38: =IF(C38="North",1,0) -> 1 | W38: =IF(C38="South",1,0) -> 0 | X38: =IF(C38="West",1,0) -> 0 | Y38: =IF(C38="East",1,0) -> 0
A39: STR-1010 | B39: 45689 | C39: North | D39: Mall | E39: 61245.41 | F39: 8156 | G39: 0.156 | H39: 19 | I39: 92.9 | J39: 9.05 | K39: =IF(ISBLANK(J39),MEDIAN($J$2:$J$321),J39) -> 9.05 | L39: =IF(ISBLANK(J39),1,0) -> 0 | M39: 0 | N39: 3.8 | O39: =IF(ISBLANK(N39),MEDIAN($N$2:$N$321),N39) -> 3.8 | P39: =IF(ISBLANK(N39),1,0) -> 0 | Q39: 718330.53 | R39: 93247.9 | S39: =IF(D39="High Street",1,0) -> 0 | T39: =IF(D39="Mall",1,0) -> 1 | U39: =IF(D39="Residential",1,0) -> 0 | V39: =IF(C39="North",1,0) -> 1 | W39: =IF(C39="South",1,0) -> 0 | X39: =IF(C39="West",1,0) -> 0 | Y39: =IF(C39="East",1,0) -> 0
A40: STR-1010 | B40: 45717 | C40: North | D40: Mall | E40: 93381.26 | F40: 7562 | G40: 0.198 | H40: 19 | I40: 82.9 | J40: 5.05 | K40: =IF(ISBLANK(J40),MEDIAN($J$2:$J$321),J40) -> 5.05 | L40: =IF(ISBLANK(J40),1,0) -> 0 | M40: 0 | N40: 4 | O40: =IF(ISBLANK(N40),MEDIAN($N$2:$N$321),N40) -> 4 | P40: =IF(ISBLANK(N40),1,0) -> 0 | Q40: 736633.4 | R40: 115654.66 | S40: =IF(D40="High Street",1,0) -> 0 | T40: =IF(D40="Mall",1,0) -> 1 | U40: =IF(D40="Residential",1,0) -> 0 | V40: =IF(C40="North",1,0) -> 1 | W40: =IF(C40="South",1,0) -> 0 | X40: =IF(C40="West",1,0) -> 0 | Y40: =IF(C40="East",1,0) -> 0
A41: STR-1010 | B41: 45748 | C41: North | D41: Mall | E41: 65012.19 | F41: 9598 | G41: 0.085 | H41: 24 | I41: 98.3 | J41: 0.89 | K41: =IF(ISBLANK(J41),MEDIAN($J$2:$J$321),J41) -> 0.89 | L41: =IF(ISBLANK(J41),1,0) -> 0 | M41: 0 | N41: 3.8 | O41: =IF(ISBLANK(N41),MEDIAN($N$2:$N$321),N41) -> 3.8 | P41: =IF(ISBLANK(N41),1,0) -> 0 | Q41: 828623.85 | R41: 167320.52 | S41: =IF(D41="High Street",1,0) -> 0 | T41: =IF(D41="Mall",1,0) -> 1 | U41: =IF(D41="Residential",1,0) -> 0 | V41: =IF(C41="North",1,0) -> 1 | W41: =IF(C41="South",1,0) -> 0 | X41: =IF(C41="West",1,0) -> 0 | Y41: =IF(C41="East",1,0) -> 0
A42: STR-1011 | B42: 45658 | C42: East | D42: Mall | E42: 40462.94 | F42: 3660 | G42: 0.218 | H42: 11 | I42: 95.2 | J42: 5.57 | K42: =IF(ISBLANK(J42),MEDIAN($J$2:$J$321),J42) -> 5.57 | L42: =IF(ISBLANK(J42),1,0) -> 0 | M42: 0 | N42: 4.4 | O42: =IF(ISBLANK(N42),MEDIAN($N$2:$N$321),N42) -> 4.4 | P42: =IF(ISBLANK(N42),1,0) -> 0 | Q42: 592195.85 | R42: 92291.56 | S42: =IF(D42="High Street",1,0) -> 0 | T42: =IF(D42="Mall",1,0) -> 1 | U42: =IF(D42="Residential",1,0) -> 0 | V42: =IF(C42="North",1,0) -> 0 | W42: =IF(C42="South",1,0) -> 0 | X42: =IF(C42="West",1,0) -> 0 | Y42: =IF(C42="East",1,0) -> 1
A43: STR-1011 | B43: 45689 | C43: East | D43: Mall | E43: 46123.88 | F43: 3227 | G43: 0.143 | H43: 10 | I43: 75.4 | J43: 1.06 | K43: =IF(ISBLANK(J43),MEDIAN($J$2:$J$321),J43) -> 1.06 | L43: =IF(ISBLANK(J43),1,0) -> 0 | M43: 0 | N43: 4.4 | O43: =IF(ISBLANK(N43),MEDIAN($N$2:$N$321),N43) -> 4.4 | P43: =IF(ISBLANK(N43),1,0) -> 0 | Q43: 532644.46 | R43: 60681.32 | S43: =IF(D43="High Street",1,0) -> 0 | T43: =IF(D43="Mall",1,0) -> 1 | U43: =IF(D43="Residential",1,0) -> 0 | V43: =IF(C43="North",1,0) -> 0 | W43: =IF(C43="South",1,0) -> 0 | X43: =IF(C43="West",1,0) -> 0 | Y43: =IF(C43="East",1,0) -> 1
A44: STR-1011 | B44: 45717 | C44: East | D44: Mall | E44: 68077.54 | F44: 3360 | G44: 0.128 | H44: 14 | I44: 88.2 | J44: 1.24 | K44: =IF(ISBLANK(J44),MEDIAN($J$2:$J$321),J44) -> 1.24 | L44: =IF(ISBLANK(J44),1,0) -> 0 | M44: 1 | N44: 4 | O44: =IF(ISBLANK(N44),MEDIAN($N$2:$N$321),N44) -> 4 | P44: =IF(ISBLANK(N44),1,0) -> 0 | Q44: 657429.18 | R44: 88919.74 | S44: =IF(D44="High Street",1,0) -> 0 | T44: =IF(D44="Mall",1,0) -> 1 | U44: =IF(D44="Residential",1,0) -> 0 | V44: =IF(C44="North",1,0) -> 0 | W44: =IF(C44="South",1,0) -> 0 | X44: =IF(C44="West",1,0) -> 0 | Y44: =IF(C44="East",1,0) -> 1
A45: STR-1011 | B45: 45748 | C45: East | D45: Mall | E45: 64882.14 | F45: 3642 | G45: 0.019 | H45: 13 | I45: 87.8 | J45: 4.52 | K45: =IF(ISBLANK(J45),MEDIAN($J$2:$J$321),J45) -> 4.52 | L45: =IF(ISBLANK(J45),1,0) -> 0 | M45: 0 | N45: 4.2 | O45: =IF(ISBLANK(N45),MEDIAN($N$2:$N$321),N45) -> 4.2 | P45: =IF(ISBLANK(N45),1,0) -> 0 | Q45: 605178 | R45: 106958.74 | S45: =IF(D45="High Street",1,0) -> 0 | T45: =IF(D45="Mall",1,0) -> 1 | U45: =IF(D45="Residential",1,0) -> 0 | V45: =IF(C45="North",1,0) -> 0 | W45: =IF(C45="South",1,0) -> 0 | X45: =IF(C45="West",1,0) -> 0 | Y45: =IF(C45="East",1,0) -> 1
A46: STR-1012 | B46: 45658 | C46: West | D46: Residential | E46: 138855.51 | F46: 5145 | G46: 0.06 | H46: 17 | I46: 88.2 | J46: 9.58 | K46: =IF(ISBLANK(J46),MEDIAN($J$2:$J$321),J46) -> 9.58 | L46: =IF(ISBLANK(J46),1,0) -> 0 | M46: 0 | N46: 3.2 | O46: =IF(ISBLANK(N46),MEDIAN($N$2:$N$321),N46) -> 3.2 | P46: =IF(ISBLANK(N46),1,0) -> 0 | Q46: 595467.6 | R46: 104276.46 | S46: =IF(D46="High Street",1,0) -> 0 | T46: =IF(D46="Mall",1,0) -> 0 | U46: =IF(D46="Residential",1,0) -> 1 | V46: =IF(C46="North",1,0) -> 0 | W46: =IF(C46="South",1,0) -> 0 | X46: =IF(C46="West",1,0) -> 1 | Y46: =IF(C46="East",1,0) -> 0
A47: STR-1012 | B47: 45689 | C47: West | D47: Residential | E47: 63630.21 | F47: 4460 | G47: 0.235 | H47: 14 | I47: 98.6 | J47: 5.52 | K47: =IF(ISBLANK(J47),MEDIAN($J$2:$J$321),J47) -> 5.52 | L47: =IF(ISBLANK(J47),1,0) -> 0 | M47: 0 | N47: 3.5 | O47: =IF(ISBLANK(N47),MEDIAN($N$2:$N$321),N47) -> 3.5 | P47: =IF(ISBLANK(N47),1,0) -> 0 | Q47: 599603.4 | R47: 112685.12 | S47: =IF(D47="High Street",1,0) -> 0 | T47: =IF(D47="Mall",1,0) -> 0 | U47: =IF(D47="Residential",1,0) -> 1 | V47: =IF(C47="North",1,0) -> 0 | W47: =IF(C47="South",1,0) -> 0 | X47: =IF(C47="West",1,0) -> 1 | Y47: =IF(C47="East",1,0) -> 0
... A72: STR-1018 | B72: 45717 | C72: East | D72: High Street | E72: 60571.82 | F72: 3193 | G72: 0.197 | H72: 7 | I72: 99 | J72: 1.43 | K72: =IF(ISBLANK(J72),MEDIAN($J$2:$J$321),J72) -> 1.43 | L72: =IF(ISBLANK(J72),1,0) -> 0 | M72: 0 | N72: 3.2 | O72: =IF(ISBLANK(N72),MEDIAN($N$2:$N$321),N72) -> 3.2 | P72: =IF(ISBLANK(N72),1,0) -> 0 | Q72: 605023.87 | R72: 98545.81 | S72: =IF(D72="High Street",1,0) -> 1 | T72: =IF(D72="Mall",1,0) -> 0 | U72: =IF(D72="Residential",1,0) -> 0 | V72: =IF(C72="North",1,0) -> 0 | W72: =IF(C72="South",1,0) -> 0 | X72: =IF(C72="West",1,0) -> 0 | Y72: =IF(C72="East",1,0) -> 1
A73: STR-1018 | B73: 45748 | C73: East | D73: High Street | E73: 55081.16 | F73: 5485 | G73: 0.036 | H73: 12 | I73: 88 | K73: =IF(ISBLANK(J73),MEDIAN($J$2:$J$321),J73) -> 3.365 | L73: =IF(ISBLANK(J73),1,0) -> 1 | M73: 0 | N73: 3.5 | O73: =IF(ISBLANK(N73),MEDIAN($N$2:$N$321),N73) -> 3.5 | P73: =IF(ISBLANK(N73),1,0) -> 0 | Q73: 674774.09 | R73: 141917.59 | S73: =IF(D73="High Street",1,0) -> 1 | T73: =IF(D73="Mall",1,0) -> 0 | U73: =IF(D73="Residential",1,0) -> 0 | V73: =IF(C73="North",1,0) -> 0 | W73: =IF(C73="South",1,0) -> 0 | X73: =IF(C73="West",1,0) -> 0 | Y73: =IF(C73="East",1,0) -> 1
A74: STR-1019 | B74: 45658 | C74: East | D74: Residential | E74: 46201.46 | F74: 5918 | G74: 0.277 | H74: 13 | I74: 78.8 | J74: 4.91 | K74: =IF(ISBLANK(J74),MEDIAN($J$2:$J$321),J74) -> 4.91 | L74: =IF(ISBLANK(J74),1,0) -> 0 | M74: 0 | N74: 4.5 | O74: =IF(ISBLANK(N74),MEDIAN($N$2:$N$321),N74) -> 4.5 | P74: =IF(ISBLANK(N74),1,0) -> 0 | Q74: 616069.41 | R74: 54453.99 | S74: =IF(D74="High Street",1,0) -> 0 | T74: =IF(D74="Mall",1,0) -> 0 | U74: =IF(D74="Residential",1,0) -> 1 | V74: =IF(C74="North",1,0) -> 0 | W74: =IF(C74="South",1,0) -> 0 | X74: =IF(C74="West",1,0) -> 0 | Y74: =IF(C74="East",1,0) -> 1
A75: STR-1019 | B75: 45689 | C75: East | D75: Residential | E75: 53762.92 | F75: 6821 | G75: 0.066 | H75: 19 | I75: 94.6 | J75: 7.03 | K75: =IF(ISBLANK(J75),MEDIAN($J$2:$J$321),J75) -> 7.03 | L75: =IF(ISBLANK(J75),1,0) -> 0 | M75: 0 | N75: 4.4 | O75: =IF(ISBLANK(N75),MEDIAN($N$2:$N$321),N75) -> 4.4 | P75: =IF(ISBLANK(N75),1,0) -> 0 | Q75: 630829.94 | R75: 117090.02 | S75: =IF(D75="High Street",1,0) -> 0 | T75: =IF(D75="Mall",1,0) -> 0 | U75: =IF(D75="Residential",1,0) -> 1 | V75: =IF(C75="North",1,0) -> 0 | W75: =IF(C75="South",1,0) -> 0 | X75: =IF(C75="West",1,0) -> 0 | Y75: =IF(C75="East",1,0) -> 1
A76: STR-1019 | B76: 45717 | C76: East | D76: Residential | E76: 70144.78 | F76: 6806 | G76: 0.178 | H76: 20 | I76: 93.1 | J76: 0.28 | K76: =IF(ISBLANK(J76),MEDIAN($J$2:$J$321),J76) -> 0.28 | L76: =IF(ISBLANK(J76),1,0) -> 0 | M76: 1 | N76: 4.3 | O76: =IF(ISBLANK(N76),MEDIAN($N$2:$N$321),N76) -> 4.3 | P76: =IF(ISBLANK(N76),1,0) -> 0 | Q76: 788087.68 | R76: 116803.42 | S76: =IF(D76="High Street",1,0) -> 0 | T76: =IF(D76="Mall",1,0) -> 0 | U76: =IF(D76="Residential",1,0) -> 1 | V76: =IF(C76="North",1,0) -> 0 | W76: =IF(C76="South",1,0) -> 0 | X76: =IF(C76="West",1,0) -> 0 | Y76: =IF(C76="East",1,0) -> 1
A77: STR-1019 | B77: 45748 | C77: East | D77: Residential | E77: 58749.63 | F77: 8252 | G77: 0.203 | H77: 20 | I77: 85.2 | J77: 3.61 | K77: =IF(ISBLANK(J77),MEDIAN($J$2:$J$321),J77) -> 3.61 | L77: =IF(ISBLANK(J77),1,0) -> 0 | M77: 0 | N77: 4.5 | O77: =IF(ISBLANK(N77),MEDIAN($N$2:$N$321),N77) -> 4.5 | P77: =IF(ISBLANK(N77),1,0) -> 0 | Q77: 680840.36 | R77: 68007.68 | S77: =IF(D77="High Street",1,0) -> 0 | T77: =IF(D77="Mall",1,0) -> 0 | U77: =IF(D77="Residential",1,0) -> 1 | V77: =IF(C77="North",1,0) -> 0 | W77: =IF(C77="South",1,0) -> 0 | X77: =IF(C77="West",1,0) -> 0 | Y77: =IF(C77="East",1,0) -> 1
A78: STR-1020 | B78: 45658 | C78: South | D78: High Street | E78: 56973.18 | F78: 6662 | G78: 0.1 | H78: 15 | I78: 77.7 | J78: 7.52 | K78: =IF(ISBLANK(J78),MEDIAN($J$2:$J$321),J78) -> 7.52 | L78: =IF(ISBLANK(J78),1,0) -> 0 | M78: 1 | N78: 3.2 | O78: =IF(ISBLANK(N78),MEDIAN($N$2:$N$321),N78) -> 3.2 | P78: =IF(ISBLANK(N78),1,0) -> 0 | Q78: 643657.47 | R78: 87022.45 | S78: =IF(D78="High Street",1,0) -> 1 | T78: =IF(D78="Mall",1,0) -> 0 | U78: =IF(D78="Residential",1,0) -> 0 | V78: =IF(C78="North",1,0) -> 0 | W78: =IF(C78="South",1,0) -> 1 | X78: =IF(C78="West",1,0) -> 0 | Y78: =IF(C78="East",1,0) -> 0
A79: STR-1020 | B79: 45689 | C79: South | D79: High Street | E79: 54872.82 | F79: 5962 | G79: 0.064 | H79: 12 | I79: 85.4 | J79: 2.58 | K79: =IF(ISBLANK(J79),MEDIAN($J$2:$J$321),J79) -> 2.58 | L79: =IF(ISBLANK(J79),1,0) -> 0 | M79: 0 | N79: 2.9 | O79: =IF(ISBLANK(N79),MEDIAN($N$2:$N$321),N79) -> 2.9 | P79: =IF(ISBLANK(N79),1,0) -> 0 | Q79: 691112.6 | R79: 109212.83 | S79: =IF(D79="High Street",1,0) -> 1 | T79: =IF(D79="Mall",1,0) -> 0 | U79: =IF(D79="Residential",1,0) -> 0 | V79: =IF(C79="North",1,0) -> 0 | W79: =IF(C79="South",1,0) -> 1 | X79: =IF(C79="West",1,0) -> 0 | Y79: =IF(C79="East",1,0) -> 0
A80: STR-1020 | B80: 45717 | C80: South | D80: High Street | E80: 80562.81 | F80: 7470 | G80: 0.172 | H80: 16 | I80: 83.5 | J80: 2.29 | K80: =IF(ISBLANK(J80),MEDIAN($J$2:$J$321),J80) -> 2.29 | L80: =IF(ISBLANK(J80),1,0) -> 0 | M80: 0 | N80: 3.3 | O80: =IF(ISBLANK(N80),MEDIAN($N$2:$N$321),N80) -> 3.3 | P80: =IF(ISBLANK(N80),1,0) -> 0 | Q80: 776922.17 | R80: 150701.93 | S80: =IF(D80="High Street",1,0) -> 1 | T80: =IF(D80="Mall",1,0) -> 0 | U80: =IF(D80="Residential",1,0) -> 0 | V80: =IF(C80="North",1,0) -> 0 | W80: =IF(C80="South",1,0) -> 1 | X80: =IF(C80="West",1,0) -> 0 | Y80: =IF(C80="East",1,0) -> 0
A81: STR-1020 | B81: 45748 | C81: South | D81: High Street | E81: 77999.9 | F81: 5974 | G81: 0.252 | H81: 14 | I81: 81.3 | J81: 2.39 | K81: =IF(ISBLANK(J81),MEDIAN($J$2:$J$321),J81) -> 2.39 | L81: =IF(ISBLANK(J81),1,0) -> 0 | M81: 0 | N81: 3.2 | O81: =IF(ISBLANK(N81),MEDIAN($N$2:$N$321),N81) -> 3.2 | P81: =IF(ISBLANK(N81),1,0) -> 0 | Q81: 636561.34 | R81: 93861.06 | S81: =IF(D81="High Street",1,0) -> 1 | T81: =IF(D81="Mall",1,0) -> 0 | U81: =IF(D81="Residential",1,0) -> 0 | V81: =IF(C81="North",1,0) -> 0 | W81: =IF(C81="South",1,0) -> 1 | X81: =IF(C81="West",1,0) -> 0 | Y81: =IF(C81="East",1,0) -> 0
A82: STR-1021 | B82: 45658 | C82: West | D82: Mall | E82: 60881.01 | F82: 5410 | G82: 0.179 | H82: 15 | I82: 83.9 | J82: 5.24 | K82: =IF(ISBLANK(J82),MEDIAN($J$2:$J$321),J82) -> 5.24 | L82: =IF(ISBLANK(J82),1,0) -> 0 | M82: 0 | N82: 4.6 | O82: =IF(ISBLANK(N82),MEDIAN($N$2:$N$321),N82) -> 4.6 | P82: =IF(ISBLANK(N82),1,0) -> 0 | Q82: 621369.58 | R82: 85493.64 | S82: =IF(D82="High Street",1,0) -> 0 | T82: =IF(D82="Mall",1,0) -> 1 | U82: =IF(D82="Residential",1,0) -> 0 | V82: =IF(C82="North",1,0) -> 0 | W82: =IF(C82="South",1,0) -> 0 | X82: =IF(C82="West",1,0) -> 1 | Y82: =IF(C82="East",1,0) -> 0
A83: STR-1021 | B83: 45689 | C83: West | D83: Mall | E83: 60628.38 | F83: 4451 | G83: 0.095 | H83: 10 | I83: 89.6 | J83: 3.17 | K83: =IF(ISBLANK(J83),MEDIAN($J$2:$J$321),J83) -> 3.17 | L83: =IF(ISBLANK(J83),1,0) -> 0 | M83: 0 | N83: 4.6 | O83: =IF(ISBLANK(N83),MEDIAN($N$2:$N$321),N83) -> 4.6 | P83: =IF(ISBLANK(N83),1,0) -> 0 | Q83: 682208.01 | R83: 110318.84 | S83: =IF(D83="High Street",1,0) -> 0 | T83: =IF(D83="Mall",1,0) -> 1 | U83: =IF(D83="Residential",1,0) -> 0 | V83: =IF(C83="North",1,0) -> 0 | W83: =IF(C83="South",1,0) -> 0 | X83: =IF(C83="West",1,0) -> 1 | Y83: =IF(C83="East",1,0) -> 0
A84: STR-1021 | B84: 45717 | C84: West | D84: Mall | E84: 72731.14 | F84: 4644 | G84: 0.084 | H84: 15 | I84: 87.1 | J84: 2.66 | K84: =IF(ISBLANK(J84),MEDIAN($J$2:$J$321),J84) -> 2.66 | L84: =IF(ISBLANK(J84),1,0) -> 0 | M84: 0 | N84: 4.6 | O84: =IF(ISBLANK(N84),MEDIAN($N$2:$N$321),N84) -> 4.6 | P84: =IF(ISBLANK(N84),1,0) -> 0 | Q84: 727241.86 | R84: 155810.3 | S84: =IF(D84="High Street",1,0) -> 0 | T84: =IF(D84="Mall",1,0) -> 1 | U84: =IF(D84="Residential",1,0) -> 0 | V84: =IF(C84="North",1,0) -> 0 | W84: =IF(C84="South",1,0) -> 0 | X84: =IF(C84="West",1,0) -> 1 | Y84: =IF(C84="East",1,0) -> 0
...

Sheet Simple_regression_footfall
A1: footfall | B1: monthly_sales
A2: 8302 | B2: 658832.62
A3: 8487 | B3: 634436
A4: 9113 | B4: 678722.06
A5: 9431 | B5: 658920.3
A6: 9545 | B6: 741341.44 | D6: SUMMARY OUTPUT
A7: 9792 | B7: 761835.34
A8: 10616 | B8: 806615.54 | D8: Regression Statistics
A9: 8567 | B9: 850164.26 | D9: Multiple R | E9: 0.85807071
A10: 10979 | B10: 930581.7 | D10: R Square | E10: 0.73628534
A11: 9459 | B11: 779010.94 | D11: Adjusted R Square | E11: 0.73545605
A12: 9172 | B12: 723060.76 | D12: Standard Error | E12: 53373.736
A13: 11230 | B13: 910791.94 | D13: Observations | E13: 320
A14: 12775 | B14: 922168.6
A15: 10054 | B15: 726606.28 | D15: ANOVA
A16: 8895 | B16: 746501.09 | E16: df | F16: SS | G16: MS | H16: F | I16: Significance F
A17: 10940 | B17: 834017.02 | D17: Regression | E17: 1 | F17: 2.5292643e+12 | G17: 2.5292643e+12 | H17: 887.84878 | I17: 4.7503615e-94
A18: 7057 | B18: 666152.52 | D18: Residual | E18: 318 | F18: 9.0590432e+11 | G18: 2.8487557e+09
A19: 4263 | B19: 573155.19 | D19: Total | E19: 319 | F19: 3.4351686e+12
A20: 5538 | B20: 666573.2
A21: 4865 | B21: 591619.95 | E21: Coefficients | F21: Standard Error | G21: t Stat | H21: P-value | I21: Lower 95% | J21: Upper 95% | K21: Lower 95.0% | L21: Upper 95.0%
A22: 2822 | B22: 415721.82 | D22: Intercept | E22: 446410.58 | F22: 8407.7383 | G22: 53.095205 | H22: 4.0862696e-160 | I22: 429868.76 | J22: 462952.4 | K22: 429868.76 | L22: 462952.4
A23: 2121 | B23: 491905.13 | D23: footfall | E23: 35.678031 | F23: 1.1973783 | G23: 29.796791 | H23: 4.7503615e-94 | I23: 33.322247 | J23: 38.033815 | K23: 33.322247 | L23: 38.033815
A24: 3364 | B24: 555929.4
A25: 2613 | B25: 565810.99
A26: 10218 | B26: 811771.14
A27: 8927 | B27: 800451.94 | D27: RESIDUAL OUTPUT
A28: 9315 | B28: 783672.82
A29: 7223 | B29: 701641.97 | D29: Observation | E29: Predicted monthly_sales | F29: Residuals
A30: 3988 | B30: 511844.41 | D30: 1 | E30: 742609.6 | F30: -83776.977
A31: 2390 | B31: 537383.79 | D31: 2 | E31: 749210.03 | F31: -114774.03
A32: 2471 | B32: 500173.02 | D32: 3 | E32: 771544.48 | F32: -92822.42
A33: 971 | B33: 427917.38 | D33: 4 | E33: 782890.09 | F33: -123969.79
A34: 9429 | B34: 641865.03 | D34: 5 | E34: 786957.39 | F34: -45615.95
A35: 11695 | B35: 799477.76 | D35: 6 | E35: 795769.86 | F35: -33934.523
A36: 9449 | B36: 798952.17 | D36: 7 | E36: 825168.56 | F36: -18553.021
A37: 10453 | B37: 800979.78 | D37: 8 | E37: 752064.28 | F37: 98099.985
A38: 8838 | B38: 820593.93 | D38: 9 | E38: 838119.69 | F38: 92462.014
A39: 8156 | B39: 718330.53 | D39: 10 | E39: 783889.08 | F39: -4878.1389
A40: 7562 | B40: 736633.4 | D40: 11 | E40: 773649.48 | F40: -50588.724
...

Sheet Simple_regression_marketing
A1: marketing_spend | B1: monthly_sales
A2: 70389.11 | B2: 658832.62
A3: 43827.89 | B3: 634436
A4: 59921.75 | B4: 678722.06
A5: 56856.63 | B5: 658920.3
A6: 48412.64 | B6: 741341.44 | D6: SUMMARY OUTPUT
A7: 64811.21 | B7: 761835.34
A8: 46213.45 | B8: 806615.54 | D8: Regression Statistics
A9: 68148.52 | B9: 850164.26 | D9: Multiple R | E9: 0.40895561
A10: 71838.86 | B10: 930581.7 | D10: R Square | E10: 0.16724469
A11: 68133.44 | B11: 779010.94 | D11: Adjusted R Square | E11: 0.16462596
A12: 34285.21 | B12: 723060.76 | D12: Standard Error | E12: 94846.034
A13: 67979.88 | B13: 910791.94 | D13: Observations | E13: 320
A14: 71828.26 | B14: 922168.6
A15: 55716.82 | B15: 726606.28 | D15: ANOVA
A16: 59909.51 | B16: 746501.09 | E16: df | F16: SS | G16: MS | H16: F | I16: Significance F
A17: 75305.71 | B17: 834017.02 | D17: Regression | E17: 1 | F17: 5.7451371e+11 | G17: 5.7451371e+11 | H17: 63.864873 | I17: 2.4800615e-14
A18: 48804.22 | B18: 666152.52 | D18: Residual | E18: 318 | F18: 2.8606549e+12 | G18: 8.9957701e+09
A19: 59117.9 | B19: 573155.19 | D19: Total | E19: 319 | F19: 3.4351686e+12
A20: 78831.12 | B20: 666573.2
A21: 41441.93 | B21: 591619.95 | E21: Coefficients | F21: Standard Error | G21: t Stat | H21: P-value | I21: Lower 95% | J21: Upper 95% | K21: Lower 95.0% | L21: Upper 95.0%
A22: 30356.28 | B22: 415721.82 | D22: Intercept | E22: 560777.35 | F22: 15906.906 | G22: 35.253703 | H22: 6.9528769e-112 | I22: 529481.27 | J22: 592073.42 | K22: 529481.27 | L22: 592073.42
A23: 33518.88 | B23: 491905.13 | D23: marketing_spend | E23: 2.1295753 | F23: 0.26647838 | G23: 7.9915501 | H23: 2.4800615e-14 | I23: 1.6052919 | J23: 2.6538587 | K23: 1.6052919 | L23: 2.6538587
A24: 42267.37 | B24: 555929.4
A25: 62060.43 | B25: 565810.99
A26: 57696.69 | B26: 811771.14
A27: 172415.52 | B27: 800451.94 | D27: RESIDUAL OUTPUT
A28: 55270.52 | B28: 783672.82
A29: 52715.1 | B29: 701641.97 | D29: Observation | E29: Predicted monthly_sales | F29: Residuals
A30: 68600.62 | B30: 511844.41 | D30: 1 | E30: 710676.26 | F30: -51843.637
A31: 63176.73 | B31: 537383.79 | D31: 2 | E31: 654112.14 | F31: -19676.139
A32: 44970.08 | B32: 500173.02 | D32: 3 | E32: 688385.23 | F32: -9663.1658
A33: 69816.35 | B33: 427917.38 | D33: 4 | E33: 681857.82 | F33: -22937.522
A34: 54597.83 | B34: 641865.03 | D34: 5 | E34: 663875.71 | F34: 77465.731
A35: 73771.91 | B35: 799477.76 | D35: 6 | E35: 698797.7 | F35: 63037.641
A36: 74413.88 | B36: 798952.17 | D36: 7 | E36: 659192.37 | F36: 147423.17
A37: 52483.77 | B37: 800979.78 | D37: 8 | E37: 705904.75 | F37: 144259.51
A38: 75269.87 | B38: 820593.93 | D38: 9 | E38: 713763.61 | F38: 216818.09
A39: 61245.41 | B39: 718330.53 | D39: 10 | E39: 705872.64 | F39: 73138.302
A40: 93381.26 | B40: 736633.4 | D40: 11 | E40: 633790.28 | F40: 89270.477
...

Sheet Simple_regression_avg_discount
A1: monthly_sales | B1: avg_discount_pct
A2: 658832.62 | B2: 0.042
A3: 634436 | B3: 0.168
A4: 678722.06 | B4: 0.133
A5: 658920.3 | B5: 0.142
A6: 741341.44 | B6: 0.231
A7: 761835.34 | B7: 0.112 | D7: SUMMARY OUTPUT
A8: 806615.54 | B8: 0.122
A9: 850164.26 | B9: 0.127 | D9: Regression Statistics
A10: 930581.7 | B10: 0.215 | D10: Multiple R | E10: 0.091052199
A11: 779010.94 | B11: 0.22 | D11: R Square | E11: 0.008290503
A12: 723060.76 | B12: 0.213 | D12: Adjusted R Square | E12: 0.0051719197
A13: 910791.94 | B13: 0.002 | D13: Standard Error | E13: 103502.94
A14: 922168.6 | B14: 0.116 | D14: Observations | E14: 320
A15: 726606.28 | B15: 0.146
A16: 746501.09 | B16: 0.228 | D16: ANOVA
A17: 834017.02 | B17: 0.006 | E17: df | F17: SS | G17: MS | H17: F | I17: Significance F
A18: 666152.52 | B18: 0.005 | D18: Regression | E18: 1 | F18: 2.8479276e+10 | G18: 2.8479276e+10 | H18: 2.6584196 | I18: 0.10399305
A19: 573155.19 | B19: 0.119 | D19: Residual | E19: 318 | F19: 3.4066893e+12 | G19: 1.071286e+10
A20: 666573.2 | B20: 0 | D20: Total | E20: 319 | F20: 3.4351686e+12
A21: 591619.95 | B21: 0.158
A22: 415721.82 | B22: 0.231 | E22: Coefficients | F22: Standard Error | G22: t Stat | H22: P-value | I22: Lower 95% | J22: Upper 95% | K22: Lower 95.0% | L22: Upper 95.0%
A23: 491905.13 | B23: 0.176 | D23: Intercept | E23: 697835.63 | F23: 12035.419 | G23: 57.981832 | H23: 3.8725944e-171 | I23: 674156.52 | J23: 721514.74 | K23: 674156.52 | L23: 721514.74
A24: 555929.4 | B24: 0.16 | D24: avg_discount_pct | E24: -138730.45 | F24: 85086.38 | G24: -1.6304661 | H24: 0.10399305 | I24: -306133.82 | J24: 28672.909 | K24: -306133.82 | L24: 28672.909
A25: 565810.99 | B25: 0.216
A26: 811771.14 | B26: 0.121
A27: 800451.94 | B27: 0.14
A28: 783672.82 | B28: 0.169 | D28: RESIDUAL OUTPUT
A29: 701641.97 | B29: 0.122
A30: 511844.41 | B30: 0.124 | D30: Observation | E30: Predicted monthly_sales | F30: Residuals
A31: 537383.79 | B31: 0.216 | D31: 1 | E31: 692008.95 | F31: -33176.33
A32: 500173.02 | B32: 0.136 | D32: 2 | E32: 674528.91 | F32: -40092.913
A33: 427917.38 | B33: 0.168 | D33: 3 | E33: 679384.48 | F33: -662.41911
A34: 641865.03 | B34: 0.188 | D34: 4 | E34: 678135.91 | F34: -19215.605
A35: 799477.76 | B35: 0.07 | D35: 5 | E35: 665788.89 | F35: 75552.545
A36: 798952.17 | B36: 0.039 | D36: 6 | E36: 682297.82 | F36: 79537.521
A37: 800979.78 | B37: 0.247 | D37: 7 | E37: 680910.51 | F37: 125705.03
A38: 820593.93 | B38: 0.092 | D38: 8 | E38: 680216.86 | F38: 169947.4
A39: 718330.53 | B39: 0.156 | D39: 9 | E39: 668008.58 | F39: 262573.12
A40: 736633.4 | B40: 0.198 | D40: 10 | E40: 667314.93 | F40: 111696.01
...

Sheet Multiple_regression
A1: monthly_sales | B1: marketing_spend | C1: footfall | D1: avg_discount_pct | E1: inventory_availability_pct | F1: clean_customer_rating | G1: staff_count | H1: holiday_flag | I1: store_type_high_street | J1: store_type_mall | K1: store_type_residential
A2: 658832.62 | B2: 70389.11 | C2: 8302 | D2: 0.042 | E2: 75 | F2: =Cleaned_data!O2 -> 3.1 | G2: 17 | H2: 1 | I2: =Dummy_variables!S2 -> 0 | J2: =Dummy_variables!T2 -> 0 | K2: =Dummy_variables!U2 -> 1
A3: 634436 | B3: 43827.89 | C3: 8487 | D3: 0.168 | E3: 84.4 | F3: =Cleaned_data!O3 -> 2.8 | G3: 23 | H3: 0 | I3: =Dummy_variables!S3 -> 0 | J3: =Dummy_variables!T3 -> 0 | K3: =Dummy_variables!U3 -> 1
A4: 678722.06 | B4: 59921.75 | C4: 9113 | D4: 0.133 | E4: 88 | F4: =Cleaned_data!O4 -> 3.2 | G4: 20 | H4: 0 | I4: =Dummy_variables!S4 -> 0 | J4: =Dummy_variables!T4 -> 0 | K4: =Dummy_variables!U4 -> 1
A5: 658920.3 | B5: 56856.63 | C5: 9431 | D5: 0.142 | E5: 86.9 | F5: =Cleaned_data!O5 -> 3.4 | G5: 23 | H5: 0 | I5: =Dummy_variables!S5 -> 0 | J5: =Dummy_variables!T5 -> 0 | K5: =Dummy_variables!U5 -> 1
A6: 741341.44 | B6: 48412.64 | C6: 9545 | D6: 0.231 | E6: 97.6 | F6: =Cleaned_data!O6 -> 4.2 | G6: 21 | H6: 1 | I6: =Dummy_variables!S6 -> 1 | J6: =Dummy_variables!T6 -> 0 | K6: =Dummy_variables!U6 -> 0 | M6: SUMMARY OUTPUT
A7: 761835.34 | B7: 64811.21 | C7: 9792 | D7: 0.112 | E7: 84.2 | F7: =Cleaned_data!O7 -> 4.2 | G7: 20 | H7: 0 | I7: =Dummy_variables!S7 -> 1 | J7: =Dummy_variables!T7 -> 0 | K7: =Dummy_variables!U7 -> 0
A8: 806615.54 | B8: 46213.45 | C8: 10616 | D8: 0.122 | E8: 85.2 | F8: =Cleaned_data!O8 -> 4.1 | G8: 22 | H8: 1 | I8: =Dummy_variables!S8 -> 1 | J8: =Dummy_variables!T8 -> 0 | K8: =Dummy_variables!U8 -> 0 | M8: Regression Statistics
A9: 850164.26 | B9: 68148.52 | C9: 8567 | D9: 0.127 | E9: 95.6 | F9: =Cleaned_data!O9 -> 3.9 | G9: 23 | H9: 0 | I9: =Dummy_variables!S9 -> 1 | J9: =Dummy_variables!T9 -> 0 | K9: =Dummy_variables!U9 -> 0 | M9: Multiple R | N9: 0.91001772
A10: 930581.7 | B10: 71838.86 | C10: 10979 | D10: 0.215 | E10: 88.6 | F10: =Cleaned_data!O10 -> 3.8 | G10: 26 | H10: 1 | I10: =Dummy_variables!S10 -> 0 | J10: =Dummy_variables!T10 -> 0 | K10: =Dummy_variables!U10 -> 0 | M10: R Square | N10: 0.82813225
A11: 779010.94 | B11: 68133.44 | C11: 9459 | D11: 0.22 | E11: 85 | F11: =Cleaned_data!O11 -> 4.2 | G11: 21 | H11: 0 | I11: =Dummy_variables!S11 -> 0 | J11: =Dummy_variables!T11 -> 0 | K11: =Dummy_variables!U11 -> 0 | M11: Adjusted R Square | N11: 0.82257019
A12: 723060.76 | B12: 34285.21 | C12: 9172 | D12: 0.213 | E12: 88.3 | F12: =Cleaned_data!O12 -> 3.8 | G12: 22 | H12: 1 | I12: =Dummy_variables!S12 -> 0 | J12: =Dummy_variables!T12 -> 0 | K12: =Dummy_variables!U12 -> 0 | M12: Standard Error | N12: 43711.125
A13: 910791.94 | B13: 67979.88 | C13: 11230 | D13: 0.002 | E13: 85.3 | F13: =Cleaned_data!O13 -> 3.8 | G13: 28 | H13: 0 | I13: =Dummy_variables!S13 -> 0 | J13: =Dummy_variables!T13 -> 0 | K13: =Dummy_variables!U13 -> 0 | M13: Observations | N13: 320
A14: 922168.6 | B14: 71828.26 | C14: 12775 | D14: 0.116 | E14: 81.7 | F14: =Cleaned_data!O14 -> 4.2 | G14: 30 | H14: 1 | I14: =Dummy_variables!S14 -> 0 | J14: =Dummy_variables!T14 -> 0 | K14: =Dummy_variables!U14 -> 1
A15: 726606.28 | B15: 55716.82 | C15: 10054 | D15: 0.146 | E15: 84.9 | F15: =Cleaned_data!O15 -> 4.3 | G15: 24 | H15: 0 | I15: =Dummy_variables!S15 -> 0 | J15: =Dummy_variables!T15 -> 0 | K15: =Dummy_variables!U15 -> 1 | M15: ANOVA
A16: 746501.09 | B16: 59909.51 | C16: 8895 | D16: 0.228 | E16: 88.8 | F16: =Cleaned_data!O16 -> 4.3 | G16: 23 | H16: 0 | I16: =Dummy_variables!S16 -> 0 | J16: =Dummy_variables!T16 -> 0 | K16: =Dummy_variables!U16 -> 1 | N16: df | O16: SS | P16: MS | Q16: F | R16: Significance F
A17: 834017.02 | B17: 75305.71 | C17: 10940 | D17: 0.006 | E17: 76.5 | F17: =Cleaned_data!O17 -> 4.5 | G17: 26 | H17: 0 | I17: =Dummy_variables!S17 -> 0 | J17: =Dummy_variables!T17 -> 0 | K17: =Dummy_variables!U17 -> 1 | M17: Regression | N17: 10 | O17: 2.8447739e+12 | P17: 2.8447739e+11 | Q17: 148.8894 | R17: 8.2337361e-112
A18: 666152.52 | B18: 48804.22 | C18: 7057 | D18: 0.005 | E18: 87.7 | F18: =Cleaned_data!O18 -> 3.7 | G18: 15 | H18: 0 | I18: =Dummy_variables!S18 -> 0 | J18: =Dummy_variables!T18 -> 0 | K18: =Dummy_variables!U18 -> 1 | M18: Residual | N18: 309 | O18: 5.903947e+11 | P18: 1.9106625e+09
A19: 573155.19 | B19: 59117.9 | C19: 4263 | D19: 0.119 | E19: 87.6 | F19: =Cleaned_data!O19 -> 3.6 | G19: 9 | H19: 0 | I19: =Dummy_variables!S19 -> 0 | J19: =Dummy_variables!T19 -> 0 | K19: =Dummy_variables!U19 -> 1 | M19: Total | N19: 319 | O19: 3.4351686e+12
A20: 666573.2 | B20: 78831.12 | C20: 5538 | D20: 0 | E20: 94.1 | F20: =Cleaned_data!O20 -> 3.9 | G20: 15 | H20: 0 | I20: =Dummy_variables!S20 -> 0 | J20: =Dummy_variables!T20 -> 0 | K20: =Dummy_variables!U20 -> 1
A21: 591619.95 | B21: 41441.93 | C21: 4865 | D21: 0.158 | E21: 88.3 | F21: =Cleaned_data!O21 -> 4 | G21: 16 | H21: 0 | I21: =Dummy_variables!S21 -> 0 | J21: =Dummy_variables!T21 -> 0 | K21: =Dummy_variables!U21 -> 1 | N21: Coefficients | O21: Standard Error | P21: t Stat | Q21: P-value | R21: Lower 95% | S21: Upper 95% | T21: Lower 95.0% | U21: Upper 95.0%
A22: 415721.82 | B22: 30356.28 | C22: 2822 | D22: 0.231 | E22: 84.8 | F22: =Cleaned_data!O22 -> 5 | G22: 9 | H22: 0 | I22: =Dummy_variables!S22 -> 0 | J22: =Dummy_variables!T22 -> 0 | K22: =Dummy_variables!U22 -> 1 | M22: Intercept | N22: 69706.911 | O22: 48461.984 | P22: 1.4383834 | Q22: 0.15133736 | R22: -25650.324 | S22: 165064.15 | T22: -25650.324 | U22: 165064.15
A23: 491905.13 | B23: 33518.88 | C23: 2121 | D23: 0.176 | E23: 88.5 | F23: =Cleaned_data!O23 -> 5 | G23: 8 | H23: 0 | I23: =Dummy_variables!S23 -> 0 | J23: =Dummy_variables!T23 -> 0 | K23: =Dummy_variables!U23 -> 1 | M23: marketing_spend | N23: 1.1609255 | O23: 0.12728741 | P23: 9.1205056 | Q23: 9.8346245e-18 | R23: 0.91046579 | S23: 1.4113852 | T23: 0.91046579 | U23: 1.4113852
A24: 555929.4 | B24: 42267.37 | C24: 3364 | D24: 0.16 | E24: 82 | F24: =Cleaned_data!O24 -> 4.6 | G24: 13 | H24: 1 | I24: =Dummy_variables!S24 -> 0 | J24: =Dummy_variables!T24 -> 0 | K24: =Dummy_variables!U24 -> 1 | M24: footfall | N24: 27.90495 | O24: 2.5073249 | P24: 11.129372 | Q24: 2.0293133e-24 | R24: 22.97136 | S24: 32.83854 | T24: 22.97136 | U24: 32.83854
A25: 565810.99 | B25: 62060.43 | C25: 2613 | D25: 0.216 | E25: 92.1 | F25: =Cleaned_data!O25 -> 4.7 | G25: 12 | H25: 0 | I25: =Dummy_variables!S25 -> 0 | J25: =Dummy_variables!T25 -> 0 | K25: =Dummy_variables!U25 -> 1 | M25: avg_discount_pct | N25: -73572.779 | O25: 36215.795 | P25: -2.0315108 | Q25: 0.043058663 | R25: -144833.54 | S25: -2312.0143 | T25: -144833.54 | U25: -2312.0143
A26: 811771.14 | B26: 57696.69 | C26: 10218 | D26: 0.121 | E26: 94.8 | F26: =Cleaned_data!O26 -> 3.5 | G26: 25 | H26: 0 | I26: =Dummy_variables!S26 -> 0 | J26: =Dummy_variables!T26 -> 1 | K26: =Dummy_variables!U26 -> 0 | M26: inventory_availability_pct | N26: 3129.922 | O26: 461.60043 | P26: 6.7805871 | Q26: 6.0853582e-11 | R26: 2221.6442 | S26: 4038.1997 | T26: 2221.6442 | U26: 4038.1997
A27: 800451.94 | B27: 172415.52 | C27: 8927 | D27: 0.14 | E27: 86.2 | F27: =Cleaned_data!O27 -> 3.9 | G27: 22 | H27: 0 | I27: =Dummy_variables!S27 -> 0 | J27: =Dummy_variables!T27 -> 1 | K27: =Dummy_variables!U27 -> 0 | M27: clean_customer_rating | N27: 12616.697 | O27: 4797.7601 | P27: 2.6297057 | Q27: 0.008973627 | R27: 3176.284 | S27: 22057.11 | T27: 3176.284 | U27: 22057.11
A28: 783672.82 | B28: 55270.52 | C28: 9315 | D28: 0.169 | E28: 91.9 | F28: =Cleaned_data!O28 -> 4 | G28: 23 | H28: 0 | I28: =Dummy_variables!S28 -> 0 | J28: =Dummy_variables!T28 -> 1 | K28: =Dummy_variables!U28 -> 0 | M28: staff_count | N28: 3184.9635 | O28: 1262.7517 | P28: 2.5222406 | Q28: 0.012163145 | R28: 700.28382 | S28: 5669.6432 | T28: 700.28382 | U28: 5669.6432
A29: 701641.97 | B29: 52715.1 | C29: 7223 | D29: 0.122 | E29: 84.2 | F29: =Cleaned_data!O29 -> 3.7 | G29: 16 | H29: 0 | I29: =Dummy_variables!S29 -> 0 | J29: =Dummy_variables!T29 -> 1 | K29: =Dummy_variables!U29 -> 0 | M29: holiday_flag | N29: 13822.072 | O29: 6642.1761 | P29: 2.0809554 | Q29: 0.038261307 | R29: 752.45539 | S29: 26891.689 | T29: 752.45539 | U29: 26891.689
A30: 511844.41 | B30: 68600.62 | C30: 3988 | D30: 0.124 | E30: 85 | F30: =Cleaned_data!O30 -> 3.6 | G30: 11 | H30: 0 | I30: =Dummy_variables!S30 -> 0 | J30: =Dummy_variables!T30 -> 0 | K30: =Dummy_variables!U30 -> 1 | M30: store_type_high_street | N30: -4555.9351 | O30: 6467.3404 | P30: -0.70445266 | Q30: 0.4816815 | R30: -17281.532 | S30: 8169.6622 | T30: -17281.532 | U30: 8169.6622
A31: 537383.79 | B31: 63176.73 | C31: 2390 | D31: 0.216 | E31: 87.5 | F31: =Cleaned_data!O31 -> 3.1 | G31: 9 | H31: 0 | I31: =Dummy_variables!S31 -> 0 | J31: =Dummy_variables!T31 -> 0 | K31: =Dummy_variables!U31 -> 1 | M31: store_type_mall | N31: 2922.414 | O31: 7277.0115 | P31: 0.40159535 | Q31: 0.68825946 | R31: -11396.35 | S31: 17241.178 | T31: -11396.35 | U31: 17241.178
A32: 500173.02 | B32: 44970.08 | C32: 2471 | D32: 0.136 | E32: 87.6 | F32: =Cleaned_data!O32 -> 3.7 | G32: 11 | H32: 1 | I32: =Dummy_variables!S32 -> 0 | J32: =Dummy_variables!T32 -> 0 | K32: =Dummy_variables!U32 -> 1 | M32: store_type_residential | N32: -26500.273 | O32: 6943.0994 | P32: -3.8167785 | Q32: 0.00016333454 | R32: -40162.007 | S32: -12838.538 | T32: -40162.007 | U32: -12838.538
A33: 427917.38 | B33: 69816.35 | C33: 971 | D33: 0.168 | E33: 89.9 | F33: =Cleaned_data!O33 -> 3.6 | G33: 5 | H33: 0 | I33: =Dummy_variables!S33 -> 0 | J33: =Dummy_variables!T33 -> 0 | K33: =Dummy_variables!U33 -> 1
A34: 641865.03 | B34: 54597.83 | C34: 9429 | D34: 0.188 | E34: 83.3 | F34: =Cleaned_data!O34 -> 4.2 | G34: 21 | H34: 0 | I34: =Dummy_variables!S34 -> 0 | J34: =Dummy_variables!T34 -> 0 | K34: =Dummy_variables!U34 -> 1
A35: 799477.76 | B35: 73771.91 | C35: 11695 | D35: 0.07 | E35: 84.7 | F35: =Cleaned_data!O35 -> 3.9 | G35: 25 | H35: 0 | I35: =Dummy_variables!S35 -> 0 | J35: =Dummy_variables!T35 -> 0 | K35: =Dummy_variables!U35 -> 1
A36: 798952.17 | B36: 74413.88 | C36: 9449 | D36: 0.039 | E36: 92.1 | F36: =Cleaned_data!O36 -> 3.5 | G36: 23 | H36: 0 | I36: =Dummy_variables!S36 -> 0 | J36: =Dummy_variables!T36 -> 0 | K36: =Dummy_variables!U36 -> 1 | M36: RESIDUAL OUTPUT
A37: 800979.78 | B37: 52483.77 | C37: 10453 | D37: 0.247 | E37: 99 | F37: =Cleaned_data!O37 -> 3.6 | G37: 25 | H37: 0 | I37: =Dummy_variables!S37 -> 0 | J37: =Dummy_variables!T37 -> 0 | K37: =Dummy_variables!U37 -> 1
